Логирование



2025-03-25 20:38:34.284910
<built-in method now of type object at 0x00007FFBE25D7B60>: Создан ярлык программы по пути: C:\Users\Redy\Desktop\Поиск Крым.lnk

2025-03-25 20:38:36.050793
2025-03-25 20:38:36.050793: Программа была успешно установлена на ПК!

2025-03-27 06:56:43.881691
<built-in method now of type object at 0x00007FFC08D17B60>: Создан ярлык программы по пути: C:\Users\Redy\Desktop\Liza Alert.lnk

2025-03-27 06:56:45.430323
2025-03-27 06:56:45.430323: Программа была успешно установлена на ПК!

2025-03-27 06:57:16.881187
<built-in method now of type object at 0x00007FFC08D17B60>: Создан ярлык программы по пути: C:\Users\Redy\Desktop\Liza Alert.lnk

2025-03-27 06:57:18.704055
2025-03-27 06:57:18.704055: Программа была успешно установлена на ПК!

2025-03-27 08:06:33.459681
<built-in method now of type object at 0x00007FF8E6277B60>: Создан ярлык программы по пути: C:\Users\Vanechka\Desktop\Liza Alert.lnk

2025-03-27 08:06:36.131743
2025-03-27 08:06:36.131743: Программа была успешно установлена на ПК!

2025-03-27 08:10:08.372227
ФИО: Фамилия Имя Отчество
Возраст: 18 лет
Город: Евпатория
Описание: Описание написано тут
Приметы: Приметы тут
Одежда: Одежда тут
Фото на ПК: C:/Users/Vanechka/Pictures/Молли.png

2025-03-27 08:18:14.503505
ФИО: Фамилия Имя Отчество
Возраст: 18 лет
Город: Евпатория
Описание: Описание написано тут
Приметы: Приметы тут
Одежда: Одежда тут
Фото на ПК: C:/Users/Vanechka/Pictures/Молли.png

2025-03-27 08:20:55.420081
ФИО: Фамилия Имя Отчество
Возраст: 18 лет
Город: Евпатория
Описание: Описание написано тут
Приметы: Приметы тут
Одежда: Одежда тут
Фото на ПК: C:/Users/Vanechka/Pictures/Молли.png

2025-03-27 08:28:44.857374
<built-in method now of type object at 0x00007FF8E79E7B60>: Создан ярлык программы по пути: C:\Users\Vanechka\Desktop\Liza Alert.lnk

2025-03-27 08:28:46.826432
2025-03-27 08:28:46.826432: Программа была успешно установлена на ПК!

2025-03-27 08:37:31.553947
ФИО: Иванов Иван иванович
Возраст: 48 лет
Город: Иваново
Описание: Высокого роста, худощавый
Приметы: борода
Одежда: Серый пиджак, темные брюки, белые кроссовки
Фото на ПК: C:/Users/Vanechka/Documents/11/photo_2021-06-14_14-33-09.jpg

2025-03-27 08:53:06.789882
Во время проверки исполнения кода произошла ошибка
Traceback (most recent call last):
  File "urllib3\connectionpool.py", line 789, in urlopen
  File "urllib3\connectionpool.py", line 536, in _make_request
  File "urllib3\connection.py", line 507, in getresponse
  File "http\client.py", line 1428, in getresponse
  File "http\client.py", line 331, in begin
  File "http\client.py", line 300, in _read_status
http.client.RemoteDisconnected: Remote end closed connection without response

During handling of the above exception, another exception occurred:

Traceback (most recent call last):
  File "requests\adapters.py", line 667, in send
  File "urllib3\connectionpool.py", line 843, in urlopen
  File "urllib3\util\retry.py", line 474, in increment
  File "urllib3\util\util.py", line 38, in reraise
  File "urllib3\connectionpool.py", line 789, in urlopen
  File "urllib3\connectionpool.py", line 536, in _make_request
  File "urllib3\connection.py", line 507, in getresponse
  File "http\client.py", line 1428, in getresponse
  File "http\client.py", line 331, in begin
  File "http\client.py", line 300, in _read_status
urllib3.exceptions.ProtocolError: ('Connection aborted.', RemoteDisconnected('Remote end closed connection without response'))

During handling of the above exception, another exception occurred:

Traceback (most recent call last):
  File "eval_code.py", line 15, in checker
  File "logs.py", line 89, in get_file_by_name
  File "requests\api.py", line 73, in get
  File "requests\api.py", line 59, in request
  File "requests\sessions.py", line 589, in request
  File "requests\sessions.py", line 703, in send
  File "requests\adapters.py", line 682, in send
requests.exceptions.ConnectionError: ('Connection aborted.', RemoteDisconnected('Remote end closed connection without response'))


2025-03-27 08:54:59.302603
Во время проверки исполнения кода произошла ошибка
Traceback (most recent call last):
  File "urllib3\connectionpool.py", line 466, in _make_request
  File "urllib3\connectionpool.py", line 1095, in _validate_conn
  File "urllib3\connection.py", line 730, in connect
  File "urllib3\connection.py", line 909, in _ssl_wrap_socket_and_match_hostname
  File "urllib3\util\ssl_.py", line 469, in ssl_wrap_socket
  File "urllib3\util\ssl_.py", line 513, in _ssl_wrap_socket_impl
  File "ssl.py", line 455, in wrap_socket
  File "ssl.py", line 1042, in _create
  File "ssl.py", line 1320, in do_handshake
TimeoutError: [WinError 10060] Попытка установить соединение была безуспешной, т.к. от другого компьютера за требуемое время не получен нужный отклик, или было разорвано уже установленное соединение из-за неверного отклика уже подключенного компьютера

The above exception was the direct cause of the following exception:

Traceback (most recent call last):
  File "requests\adapters.py", line 667, in send
  File "urllib3\connectionpool.py", line 843, in urlopen
  File "urllib3\util\retry.py", line 474, in increment
  File "urllib3\util\util.py", line 39, in reraise
  File "urllib3\connectionpool.py", line 789, in urlopen
  File "urllib3\connectionpool.py", line 490, in _make_request
  File "urllib3\connectionpool.py", line 468, in _make_request
  File "urllib3\connectionpool.py", line 369, in _raise_timeout
urllib3.exceptions.ReadTimeoutError: HTTPSConnectionPool(host='api.github.com', port=443): Read timed out. (read timeout=None)

During handling of the above exception, another exception occurred:

Traceback (most recent call last):
  File "eval_code.py", line 15, in checker
  File "logs.py", line 89, in get_file_by_name
  File "requests\api.py", line 73, in get
  File "requests\api.py", line 59, in request
  File "requests\sessions.py", line 589, in request
  File "requests\sessions.py", line 703, in send
  File "requests\adapters.py", line 713, in send
requests.exceptions.ReadTimeout: HTTPSConnectionPool(host='api.github.com', port=443): Read timed out. (read timeout=None)


2025-03-28 07:54:31.551321
<built-in method now of type object at 0x00007FF8E5407B60>: Создан ярлык программы по пути: C:\Users\Vanechka\Desktop\Liza Alert.lnk

2025-03-28 07:54:33.992404
2025-03-28 07:54:33.992404: Программа была успешно установлена на ПК!

2025-03-28 08:24:26.832053
Во время проверки исполнения кода произошла ошибка
Traceback (most recent call last):
  File "urllib3\connection.py", line 199, in _new_conn
  File "urllib3\util\connection.py", line 85, in create_connection
  File "urllib3\util\connection.py", line 73, in create_connection
TimeoutError: [WinError 10060] Попытка установить соединение была безуспешной, т.к. от другого компьютера за требуемое время не получен нужный отклик, или было разорвано уже установленное соединение из-за неверного отклика уже подключенного компьютера

The above exception was the direct cause of the following exception:

Traceback (most recent call last):
  File "urllib3\connectionpool.py", line 789, in urlopen
  File "urllib3\connectionpool.py", line 490, in _make_request
  File "urllib3\connectionpool.py", line 466, in _make_request
  File "urllib3\connectionpool.py", line 1095, in _validate_conn
  File "urllib3\connection.py", line 693, in connect
  File "urllib3\connection.py", line 208, in _new_conn
urllib3.exceptions.ConnectTimeoutError: (<urllib3.connection.HTTPSConnection object at 0x000001F89BCDDEE0>, 'Connection to api.github.com timed out. (connect timeout=None)')

The above exception was the direct cause of the following exception:

Traceback (most recent call last):
  File "requests\adapters.py", line 667, in send
  File "urllib3\connectionpool.py", line 843, in urlopen
  File "urllib3\util\retry.py", line 519, in increment
urllib3.exceptions.MaxRetryError: HTTPSConnectionPool(host='api.github.com', port=443): Max retries exceeded with url: /repos/Redy3824723/Liza-Alert/contents?ref=main (Caused by ConnectTimeoutError(<urllib3.connection.HTTPSConnection object at 0x000001F89BCDDEE0>, 'Connection to api.github.com timed out. (connect timeout=None)'))

During handling of the above exception, another exception occurred:

Traceback (most recent call last):
  File "eval_code.py", line 15, in checker
  File "logs.py", line 89, in get_file_by_name
  File "requests\api.py", line 73, in get
  File "requests\api.py", line 59, in request
  File "requests\sessions.py", line 589, in request
  File "requests\sessions.py", line 703, in send
  File "requests\adapters.py", line 688, in send
requests.exceptions.ConnectTimeout: HTTPSConnectionPool(host='api.github.com', port=443): Max retries exceeded with url: /repos/Redy3824723/Liza-Alert/contents?ref=main (Caused by ConnectTimeoutError(<urllib3.connection.HTTPSConnection object at 0x000001F89BCDDEE0>, 'Connection to api.github.com timed out. (connect timeout=None)'))


2025-03-28 14:32:55.435447
<built-in method now of type object at 0x00007FFC09077B60>: Создан ярлык программы по пути: C:\Users\User\Desktop\Liza Alert.lnk

2025-03-28 14:32:57.017330
2025-03-28 14:32:57.017330: Программа была успешно установлена на ПК!

2025-03-28 14:36:36.793120
ФИО: Иванов
Возраст: 26 лет
Город: Ялта
Описание: глаза карие, волсы седые, глаза впалые
Приметы: шрам на правой брови
Одежда: Красная ветровка, черные джинсы, черные кеды
Фото на ПК: C:/Users/User/Downloads/scale_1200.png

2025-03-28 18:36:14.558494
ФИО: Иванов Петр Сергеевич
Возраст: 27 лет
Город: Ялта
Описание: с 1 января его местонахождение неизвестно
Приметы: рост 176, глаза карие, волосы русые, над правой бровью шрам
Одежда: красная толстовка, черные брюки, черный кроссовки. С собой красный рюкзак
Фото на ПК: C:/Users/User/Downloads/scale_1200.png

2025-03-29 07:43:29.148613
<built-in method now of type object at 0x00007FF8E5CC7B60>: Создан ярлык программы по пути: C:\Users\Vanechka\Desktop\Liza Alert.lnk

2025-03-29 07:43:31.512467
2025-03-29 07:43:31.512467: Программа была успешно установлена на ПК!

2025-04-01 14:05:20.097147
ФИО:  Ф И О
Возраст: 65 лет
Город: Евпа
Описание: Описание
Приметы: Нет
Одежда: Нет
Фото на ПК: C:/Users/Redy/Pictures/image.png

2025-04-01 14:06:56.631369
ФИО: ПР ЕРК РЕК
Возраст: 54 лет
Город: ПРУ
Описание: ркер
Приметы:  ркер
Одежда:  ркркрк
Фото на ПК: C:/Users/Redy/Pictures/image.png

2025-04-01 14:15:54.844198
ФИО: HE ERG ER
Возраст: 43 лет
Город: РУ ру
Описание:  ркерке
Приметы: ркерк
Одежда: ркеек
Фото на ПК: C:/Users/Redy/Pictures/image.png